Workbook
Name Slicer_category: #N/A
Name Slicer_month: #N/A
Name Slicer_sales_channel: #N/A
Name Slicer_warehouse: #N/A

Sheet Executive KPI report
A1: Revenue | B1: Orders | C1: Gross Margin % | D1: Inventory Value | E1: Inventory Turnover | F1: Freight % | G1: Fill Rate | H1: Stockout Risk SKUs
A2: =SUM(Table5[revenue]) -> 761103.07 | B2: =COUNTA(Table1[order_id]) -> 450 | C2: =ROUND(SUM(Table5[margin])/'Executive KPI report'!A2,2) -> 0.87 | D2: =SUM(inventory!O2:O313) -> 6745761.4 | E2: =SUM(inventory!M2:M313) -> 63.57 | F2: =ROUND(freight_dashboard!A2/SUM(Table5[revenue]),2) -> 0.04 | G2: =ROUND((COUNTIF(Table1[order_status],"Shipped")+COUNTIF(Table1[order_status],"Delivered"))/B2,2) -> 0.68 | H2: =COUNTIF(inventory!Q2:Q313,"Reorder") -> 4
A5: slow_moving | B5: Slow Moving
A6: Inventory Reduction
A7: SKU | B7: Sum of inventory_value
A8: SKU-0026 | B8: 148318.3
A9: SKU-0069 | B9: 116772.79
A10: SKU-0041 | B10: 56548.44
A11: SKU-0011 | B11: 22538.06
A12: Grand Total | B12: 344177.59

Sheet supplier scoreboard
A1: supplier_name | B1: Total POs | C1: Avg Lead Time | D1: On-Time_count | E1: On-Time % | F1: Late Deliveries | G1: Fill Rate
A2: {=_xlfn._xlws.SORT(_xlfn.UNIQUE(Table2[supplier_name]))} -> Acme Supply | B2: =COUNTIF(purchase_orders!M2:M501,'supplier scoreboard'!A2) -> 55 | C2: =ROUND(SUMIFS(purchase_orders!L2:L501,purchase_orders!M2:M501,'supplier scoreboard'!A2)/B2,2) -> 33.38 | D2: =COUNTIFS(purchase_orders!N2:N501,"On time",purchase_orders!M2:M501,'supplier scoreboard'!A2) -> 8 | E2: =ROUND(D2/B2,2) -> 0.15 | F2: =COUNTIFS(purchase_orders!N2:N501,"Late",purchase_orders!M2:M501,'supplier scoreboard'!A2) -> 47 | G2: =ROUND(SUMIFS(purchase_orders!O2:O501,purchase_orders!M2:M501,'supplier scoreboard'!A2)/'supplier scoreboard'!B2,2) -> 0.87
A3: Blue Ridge | B3: =COUNTIF(purchase_orders!M3:M502,'supplier scoreboard'!A3) -> 67 | C3: =ROUND(SUMIFS(purchase_orders!L3:L502,purchase_orders!M3:M502,'supplier scoreboard'!A3)/B3,2) -> 27.36 | D3: =COUNTIFS(purchase_orders!N3:N502,"On time",purchase_orders!M3:M502,'supplier scoreboard'!A3) -> 8 | E3: =ROUND(D3/B3,2) -> 0.12 | F3: =COUNTIFS(purchase_orders!N3:N502,"Late",purchase_orders!M3:M502,'supplier scoreboard'!A3) -> 59 | G3: =ROUND(SUMIFS(purchase_orders!O3:O502,purchase_orders!M3:M502,'supplier scoreboard'!A3)/'supplier scoreboard'!B3,2) -> 0.75
A4: Evergreen Imports | B4: =COUNTIF(purchase_orders!M4:M503,'supplier scoreboard'!A4) -> 77 | C4: =ROUND(SUMIFS(purchase_orders!L4:L503,purchase_orders!M4:M503,'supplier scoreboard'!A4)/B4,2) -> 31.34 | D4: =COUNTIFS(purchase_orders!N4:N503,"On time",purchase_orders!M4:M503,'supplier scoreboard'!A4) -> 15 | E4: =ROUND(D4/B4,2) -> 0.19 | F4: =COUNTIFS(purchase_orders!N4:N503,"Late",purchase_orders!M4:M503,'supplier scoreboard'!A4) -> 62 | G4: =ROUND(SUMIFS(purchase_orders!O4:O503,purchase_orders!M4:M503,'supplier scoreboard'!A4)/'supplier scoreboard'!B4,2) -> 0.84
A5: Global Goods | B5: =COUNTIF(purchase_orders!M5:M504,'supplier scoreboard'!A5) -> 59 | C5: =ROUND(SUMIFS(purchase_orders!L5:L504,purchase_orders!M5:M504,'supplier scoreboard'!A5)/B5,2) -> 28.47 | D5: =COUNTIFS(purchase_orders!N5:N504,"On time",purchase_orders!M5:M504,'supplier scoreboard'!A5) -> 9 | E5: =ROUND(D5/B5,2) -> 0.15 | F5: =COUNTIFS(purchase_orders!N5:N504,"Late",purchase_orders!M5:M504,'supplier scoreboard'!A5) -> 50 | G5: =ROUND(SUMIFS(purchase_orders!O5:O504,purchase_orders!M5:M504,'supplier scoreboard'!A5)/'supplier scoreboard'!B5,2) -> 0.76
A6: Metro Logistics | B6: =COUNTIF(purchase_orders!M6:M505,'supplier scoreboard'!A6) -> 55 | C6: =ROUND(SUMIFS(purchase_orders!L6:L505,purchase_orders!M6:M505,'supplier scoreboard'!A6)/B6,2) -> 30.18 | D6: =COUNTIFS(purchase_orders!N6:N505,"On time",purchase_orders!M6:M505,'supplier scoreboard'!A6) -> 4 | E6: =ROUND(D6/B6,2) -> 0.07 | F6: =COUNTIFS(purchase_orders!N6:N505,"Late",purchase_orders!M6:M505,'supplier scoreboard'!A6) -> 51 | G6: =ROUND(SUMIFS(purchase_orders!O6:O505,purchase_orders!M6:M505,'supplier scoreboard'!A6)/'supplier scoreboard'!B6,2) -> 0.75
A7: PrimeSource | B7: =COUNTIF(purchase_orders!M7:M506,'supplier scoreboard'!A7) -> 70 | C7: =ROUND(SUMIFS(purchase_orders!L7:L506,purchase_orders!M7:M506,'supplier scoreboard'!A7)/B7,2) -> 30.16 | D7: =COUNTIFS(purchase_orders!N7:N506,"On time",purchase_orders!M7:M506,'supplier scoreboard'!A7) -> 13 | E7: =ROUND(D7/B7,2) -> 0.19 | F7: =COUNTIFS(purchase_orders!N7:N506,"Late",purchase_orders!M7:M506,'supplier scoreboard'!A7) -> 57 | G7: =ROUND(SUMIFS(purchase_orders!O7:O506,purchase_orders!M7:M506,'supplier scoreboard'!A7)/'supplier scoreboard'!B7,2) -> 0.85
A8: Summit Trading | B8: =COUNTIF(purchase_orders!M8:M507,'supplier scoreboard'!A8) -> 49 | C8: =ROUND(SUMIFS(purchase_orders!L8:L507,purchase_orders!M8:M507,'supplier scoreboard'!A8)/B8,2) -> 30.2 | D8: =COUNTIFS(purchase_orders!N8:N507,"On time",purchase_orders!M8:M507,'supplier scoreboard'!A8) -> 6 | E8: =ROUND(D8/B8,2) -> 0.12 | F8: =COUNTIFS(purchase_orders!N8:N507,"Late",purchase_orders!M8:M507,'supplier scoreboard'!A8) -> 43 | G8: =ROUND(SUMIFS(purchase_orders!O8:O507,purchase_orders!M8:M507,'supplier scoreboard'!A8)/'supplier scoreboard'!B8,2) -> 0.83
A9: Utah Wholesale | B9: =COUNTIF(purchase_orders!M9:M508,'supplier scoreboard'!A9) -> 62 | C9: =ROUND(SUMIFS(purchase_orders!L9:L508,purchase_orders!M9:M508,'supplier scoreboard'!A9)/B9,2) -> 32.76 | D9: =COUNTIFS(purchase_orders!N9:N508,"On time",purchase_orders!M9:M508,'supplier scoreboard'!A9) -> 11 | E9: =ROUND(D9/B9,2) -> 0.18 | F9: =COUNTIFS(purchase_orders!N9:N508,"Late",purchase_orders!M9:M508,'supplier scoreboard'!A9) -> 51 | G9: =ROUND(SUMIFS(purchase_orders!O9:O508,purchase_orders!M9:M508,'supplier scoreboard'!A9)/'supplier scoreboard'!B9,2) -> 0.86

Sheet freight_dashboard
A1: Total freight cost | B1: freight % revenue | C1: shipments | D1: cost per unit
A2: =SUM(Table3[freight_cost]) -> 29211.12 | B2: =ROUND(A2/SUM(Table5[revenue]),2) -> 0.04 | C2: =COUNTA(Table3[shipment_id]) -> 403 | D2: =ROUND(A2/SUM(Table3[quantity]),2) -> 6.7
A6: carrier | B6: Sum of freight_cost | C6: Count of shipment_id | D6: delay rate
A7: FEDEX | B7: 6346.93 | C7: 77 | D7: =ROUND(COUNTIFS(Table3[shipment_status],"Late",Table3[carrier],freight_dashboard!A7)/C7,2) -> 0.48
A8: DHL | B8: 5273.1 | C8: 70 | D8: =ROUND(COUNTIFS(Table3[shipment_status],"Late",Table3[carrier],freight_dashboard!A8)/C8,2) -> 0.41
A9: UPS | B9: 5142.42 | C9: 70 | D9: =ROUND(COUNTIFS(Table3[shipment_status],"Late",Table3[carrier],freight_dashboard!A9)/C9,2) -> 0.37
A10: XPO | B10: 4441.03 | C10: 62 | D10: =ROUND(COUNTIFS(Table3[shipment_status],"Late",Table3[carrier],freight_dashboard!A10)/C10,2) -> 0.44
A11: ONTRAC | B11: 4406.23 | C11: 68 | D11: =ROUND(COUNTIFS(Table3[shipment_status],"Late",Table3[carrier],freight_dashboard!A11)/C11,2) -> 0.37
A12: USPS | B12: 3601.41 | C12: 56 | D12: =ROUND(COUNTIFS(Table3[shipment_status],"Late",Table3[carrier],freight_dashboard!A12)/C12,2) -> 0.36
A13: Grand Total | B13: 29211.12 | C13: 403
A15: shipment_status | B15: Late
A17: carrier | B17: Count of shipment_status
A18: DHL | B18: 29
A19: FEDEX | B19: 37
A20: ONTRAC | B20: 25
A21: UPS | B21: 26
A22: USPS | B22: 20
A23: XPO | B23: 27
A24: Grand Total | B24: 164

Sheet inventory dashboard
A1: inventory value | B1: units_on_hand | C1: slow-moving skus | D1: stockout risk | E1: turnover
A2: =SUM(inventory!O2:O313) -> 6745761.4 | B2: =SUM(inventory!D2:D313) -> 74652 | C2: =COUNTIF(inventory!P2:P313,"Slow Moving") -> 11 | D2: =COUNTIF(inventory!Q2:Q313,"Reorder") -> 4 | E2: =SUM(inventory!M2:M313) -> 63.57

Sheet sales dashboard
A1: Revenue | B1: Orders | C1: Units_sold | D1: Margin%
A2: =SUM(order_items!G2:G1109) -> 761103.07 | B2: =COUNT(Table1[order_id]) -> 450 | C2: =SUM(Table5[quantity]) -> 4928 | D2: =ROUND(SUM(Table5[margin])/A2,2) -> 0.87
A5: week | B5: Sum of revenue
A6: 2026-w01 | B6: 19301.68
A7: 2026-w02 | B7: 38590.43
A8: 2026-w03 | B8: 34268.25
A9: 2026-w04 | B9: 38340.21
A10: 2026-w05 | B10: 37993.34
A11: 2026-w06 | B11: 30131.87
A12: 2026-w07 | B12: 28983.9
A13: 2026-w08 | B13: 43753.74
A14: 2026-w09 | B14: 39693.39
A15: 2026-w10 | B15: 42958.42
A16: 2026-w11 | B16: 40347.8
A17: 2026-w12 | B17: 48234.27
... A26: Grand Total | B26: 761103.07
A29: sales_channel | B29: Sum of revenue | D29: sku | E29: Sum of revenue
A30: Shopify | B30: 291056.78 | D30: SKU-0081 | E30: 18496.35
A31: Amazon | B31: 225306.35 | D31: SKU-0098 | E31: 16567.12
A32: Ebay | B32: 139848.5 | D32: SKU-0117 | E32: 16114.81
A33: Walmart | B33: 104891.44 | D33: SKU-0043 | E33: 14909.79
A34: Grand Total | B34: 761103.07 | D34: SKU-0109 | E34: 14400.96
D35: SKU-0125 | E35: 13674.56
D36: SKU-0082 | E36: 13351.15
D37: SKU-0006 | E37: 13076.42
D38: SKU-0048 | E38: 12867.3
D39: SKU-0061 | E39: 12583.64
D40: SKU-0017 | E40: 12566.68
D41: SKU-0091 | E41: 10534.22
D42: SKU-0079 | E42: 10290.84
D43: SKU-0107 | E43: 10254.51
D44: SKU-0019 | E44: 10147.39
D45: SKU-0046 | E45: 9634.61
D46: SKU-0083 | E46: 9390.45
... D50: Grand Total | E50: 246274.2
A54: category | B54: Sum of margin
A55: Home | B55: 135566.95
A56: Beauty | B56: 115130.85
A57: Pet | B57: 103806.03
A58: Office | B58: 97157.88
...

Sheet sales_by_channel
A1: sales_channel | B1: revenue | C1: Orders | D1: Gross Margin | E1: Margin % | F1: Freight % | J1: KPI | K1: Value | M1: category | N1: Sum of revenue | O1: Sum of margin | P1: margin%
A2: {=_xlfn._xlws.SORT(_xlfn.UNIQUE(customer_orders!D2:D451))} -> Amazon | B2: =SUMIFS(order_items!G:G,order_items!M:M,sales_by_channel!A2) -> 225306.35 | C2: =COUNTIFS(customer_orders!D:D,sales_by_channel!A2) -> 146 | D2: =SUMIFS(order_items!P:P,order_items!M:M,sales_by_channel!A2) -> 194446.7 | E2: =ROUND(D2/B2,2) -> 0.86 | F2: =ROUND(SUMIFS(order_items!K:K,order_items!M:M,sales_by_channel!A2)/B2,2) -> 0.1 | J2: Total revenue | K2: =SUM(order_items!G:G) -> 761103.07 | M2: Home | N2: 150510.45 | O2: 135566.95 | P2: =ROUND(O2/N2,2) -> 0.9
A3: Ebay | B3: =SUMIFS(order_items!G:G,order_items!M:M,sales_by_channel!A3) -> 139848.5 | C3: =COUNTIFS(customer_orders!D:D,sales_by_channel!A3) -> 76 | D3: =SUMIFS(order_items!P:P,order_items!M:M,sales_by_channel!A3) -> 123005.9 | E3: =ROUND(D3/B3,2) -> 0.88 | F3: =ROUND(SUMIFS(order_items!K:K,order_items!M:M,sales_by_channel!A3)/B3,2) -> 0.08 | J3: Gross Margin | K3: =K2-SUM(order_items!P:P) -> 97417.97 | M3: Beauty | N3: 133230.23 | O3: 115130.85 | P3: =ROUND(O3/N3,2) -> 0.86
A4: Shopify | B4: =SUMIFS(order_items!G:G,order_items!M:M,sales_by_channel!A4) -> 291056.78 | C4: =COUNTIFS(customer_orders!D:D,sales_by_channel!A4) -> 160 | D4: =SUMIFS(order_items!P:P,order_items!M:M,sales_by_channel!A4) -> 254569.39 | E4: =ROUND(D4/B4,2) -> 0.87 | F4: =ROUND(SUMIFS(order_items!K:K,order_items!M:M,sales_by_channel!A4)/B4,2) -> 0.09 | J4: Orders | K4: =COUNT(order_items!A:A) -> 1108 | M4: Pet | N4: 117600.35 | O4: 103806.03 | P4: =ROUND(O4/N4,2) -> 0.88
A5: Walmart | B5: =SUMIFS(order_items!G:G,order_items!M:M,sales_by_channel!A5) -> 104891.44 | C5: =COUNTIFS(customer_orders!D:D,sales_by_channel!A5) -> 68 | D5: =SUMIFS(order_items!P:P,order_items!M:M,sales_by_channel!A5) -> 91663.11 | E5: =ROUND(D5/B5,2) -> 0.87 | F5: =ROUND(SUMIFS(order_items!K:K,order_items!M:M,sales_by_channel!A5)/B5,2) -> 0.11 | J5: Inventory Value | K5: =SUM(products!K2:K154) -> 3577292.3 | M5: Office | N5: 112945.63 | O5: 97157.88 | P5: =ROUND(O5/N5,2) -> 0.86
J6: Margin % | K6: =ROUND(K3/K2,2) -> 0.13 | M6: Electronics | N6: 89138.16 | O6: 74916.84 | P6: =ROUND(O6/N6,2) -> 0.84
J7: Freight % | K7: =ROUND(SUM(shipments!H:H)/K2,2) -> 0.04 | M7: Sports | N7: 86895.83 | O7: 73893.18 | P7: =ROUND(O7/N7,2) -> 0.85
J8: AOV | K8: =ROUND(K2/K4,2) -> 686.92 | M8: Toys | N8: 39841.07 | O8: 34653.66 | P8: =ROUND(O8/N8,2) -> 0.87
M9: Kitchen | N9: 30941.35 | O9: 28559.71 | P9: =ROUND(O9/N9,2) -> 0.92
M10: Grand Total | N10: 761103.07 | O10: 663685.1
J11: shipment_status | K11: Late
A13: supplier_name | B13: avg_lead_time | D13: warehouse | E13: freight_cost | F13: warehouse | G13: Sum of freight_cost | J13: carrier | K13: Count of shipment_status
A14: {=_xlfn._xlws.SORT(_xlfn.UNIQUE(suppliers!B2:B9))} -> Acme Supply | B14: =ROUND(AVERAGEIFS(purchase_orders!L:L,purchase_orders!M:M,sales_by_channel!A14),2) -> 36 | D14: {=_xlfn._xlws.SORT(_xlfn.UNIQUE(inventory!C2:C313))} -> Draper | E14: =SUMIFS(order_items!K:K,order_items!N:N,sales_by_channel!D14) -> 14340.12 | F14: South Jordan | G14: 17546.47 | J14: DHL | K14: 29
A15: Blue Ridge | B15: =ROUND(AVERAGEIFS(purchase_orders!L:L,purchase_orders!M:M,sales_by_channel!A15),2) -> 31.07 | D15: Lehi | E15: =SUMIFS(order_items!K:K,order_items!N:N,sales_by_channel!D15) -> 8545.29 | F15: Draper | G15: 14340.12 | J15: FEDEX | K15: 37
A16: Evergreen Imports | B16: =ROUND(AVERAGEIFS(purchase_orders!L:L,purchase_orders!M:M,sales_by_channel!A16),2) -> 33.99 | D16: Salt Lake City | E16: =SUMIFS(order_items!K:K,order_items!N:N,sales_by_channel!D16) -> 14259.47 | F16: Salt Lake City | G16: 14259.47 | J16: ONTRAC | K16: 25
A17: Global Goods | B17: =ROUND(AVERAGEIFS(purchase_orders!L:L,purchase_orders!M:M,sales_by_channel!A17),2) -> 33.29 | D17: South Jordan | E17: =SUMIFS(order_items!K:K,order_items!N:N,sales_by_channel!D17) -> 17546.47 | F17: Lehi | G17: 8545.29 | J17: UPS | K17: 26
A18: Metro Logistics | B18: =ROUND(AVERAGEIFS(purchase_orders!L:L,purchase_orders!M:M,sales_by_channel!A18),2) -> 34.58 | D18: Unknown | E18: =SUMIFS(order_items!K:K,order_items!N:N,sales_by_channel!D18) -> 8340.72 | F18: Unknown | G18: 8340.72 | J18: USPS | K18: 20
A19: PrimeSource | B19: =ROUND(AVERAGEIFS(purchase_orders!L:L,purchase_orders!M:M,sales_by_channel!A19),2) -> 33.17 | D19: West Valley | E19: =SUMIFS(order_items!K:K,order_items!N:N,sales_by_channel!D19) -> 7323.34 | F19: West Valley | G19: 7323.34 | J19: XPO | K19: 27
A20: Summit Trading | B20: =ROUND(AVERAGEIFS(purchase_orders!L:L,purchase_orders!M:M,sales_by_channel!A20),2) -> 33.21 | F20: Grand Total | G20: 70355.41 | J20: Grand Total | K20: 164
A21: Utah Wholesale | B21: =ROUND(AVERAGEIFS(purchase_orders!L:L,purchase_orders!M:M,sales_by_channel!A21),2) -> 34.87

Sheet warehouse_inventory_balance
A1: warehouse | B1: Sum of quantity_on_hand | C1: order_count
A2: Draper | B2: 13009 | C2: =COUNTIFS(order_items!N:N,warehouse_inventory_balance!A2) -> 240
A3: Lehi | B3: 6885 | C3: =COUNTIFS(order_items!N:N,warehouse_inventory_balance!A3) -> 118
A4: Salt Lake City | B4: 14793 | C4: =COUNTIFS(order_items!N:N,warehouse_inventory_balance!A4) -> 218
A5: South Jordan | B5: 20574 | C5: =COUNTIFS(order_items!N:N,warehouse_inventory_balance!A5) -> 297
A6: Unknown | B6: 8923 | C6: =COUNTIFS(order_items!N:N,warehouse_inventory_balance!A6) -> 118
A7: West Valley | B7: 10468 | C7: =COUNTIFS(order_items!N:N,warehouse_inventory_balance!A7) -> 117
A8: Grand Total | B8: 74652 | C8: =COUNTIFS(order_items!N:N,warehouse_inventory_balance!A8) -> 0

Sheet weekly sales trend chart.
A1: week | B1: Sum of revenue
A2: 2026-w01 | B2: 19301.68
A3: 2026-w02 | B3: 38590.43
A4: 2026-w03 | B4: 34268.25
A5: 2026-w04 | B5: 38340.21
A6: 2026-w05 | B6: 37993.34
A7: 2026-w06 | B7: 30131.87
A8: 2026-w07 | B8: 28983.9
A9: 2026-w08 | B9: 43753.74
A10: 2026-w09 | B10: 39693.39
A11: 2026-w10 | B11: 42958.42
A12: 2026-w11 | B12: 40347.8
A13: 2026-w12 | B13: 48234.27
... A22: Grand Total | B22: 761103.07
A25: sales_channel | B25: Sum of revenue
A26: Shopify | B26: 291056.78
A27: Amazon | B27: 225306.35
A28: Ebay | B28: 139848.5
A29: Walmart | B29: 104891.44
A30: Grand Total | B30: 761103.07
A44: sku | B44: Sum of revenue
A45: SKU-0081 | B45: 18496.35
A46: SKU-0098 | B46: 16567.12
A47: SKU-0117 | B47: 16114.81
A48: SKU-0043 | B48: 14909.79
A49: SKU-0109 | B49: 14400.96
A50: SKU-0125 | B50: 13674.56
A51: SKU-0082 | B51: 13351.15
A52: SKU-0006 | B52: 13076.42
A53: SKU-0048 | B53: 12867.3
A54: SKU-0061 | B54: 12583.64
A55: SKU-0017 | B55: 12566.68
A56: SKU-0091 | B56: 10534.22
... A65: Grand Total | B65: 246274.2

Sheet reorder_point
A1: SKU | B1: product_id | C1: Quantity_on_hand | D1: Units_sold | E1: order_date_count | F1: avg_daily_sales | G1: lead_time | H1: reorder_point | I1: reorder | J1: duplicate_sku
A2: {=_xlfn._xlws.SORT(_xlfn.UNIQUE(order_items!I2:I1109))} -> SKU-0001 | B2: =_xlfn.XLOOKUP(A2,order_items!I:I,order_items!C:C) -> 1 | C2: =_xlfn.XLOOKUP(B2,inventory!B:B,inventory!D:D) -> 22 | D2: =SUMIFS(order_items!D:D,order_items!C:C,reorder_point!B2) -> 16 | E2: =COUNT(customer_orders!A2:A451) -> 450 | F2: =ROUND(D2/E2,2) -> 0.04 | G2: =IFERROR(_xlfn.XLOOKUP(B2,purchase_orders!C:C,purchase_orders!L:L),"") -> 40 | H2: =IFERROR(F2*G2+10,"") -> 11.6 | I2: =IF(H2="","",IF(C2<H2,"Reorder","OK")) -> OK | J2: =COUNTIF(A2:A151,A2)>1 -> FALSE
A3: SKU-0002 | B3: =_xlfn.XLOOKUP(A3,order_items!I:I,order_items!C:C) -> 2 | C3: =_xlfn.XLOOKUP(B3,inventory!B:B,inventory!D:D) -> 405 | D3: =SUMIFS(order_items!D:D,order_items!C:C,reorder_point!B3) -> 37 | E3: =450 -> 450 | F3: =ROUND(D3/E3,2) -> 0.08 | G3: =IFERROR(_xlfn.XLOOKUP(B3,purchase_orders!C:C,purchase_orders!L:L),"") -> 32 | H3: =IFERROR(F3*G3+10,"") -> 12.56 | I3: =IF(H3="","",IF(C3<H3,"Reorder","OK")) -> OK | J3: =COUNTIF(A3:A152,A3)>1 -> FALSE
A4: SKU-0003 | B4: =_xlfn.XLOOKUP(A4,order_items!I:I,order_items!C:C) -> 3 | C4: =_xlfn.XLOOKUP(B4,inventory!B:B,inventory!D:D) -> 51 | D4: =SUMIFS(order_items!D:D,order_items!C:C,reorder_point!B4) -> 27 | E4: =450 -> 450 | F4: =ROUND(D4/E4,2) -> 0.06 | G4: =IFERROR(_xlfn.XLOOKUP(B4,purchase_orders!C:C,purchase_orders!L:L),"") -> 14 | H4: =IFERROR(F4*G4+10,"") -> 10.84 | I4: =IF(H4="","",IF(C4<H4,"Reorder","OK")) -> OK | J4: =COUNTIF(A4:A153,A4)>1 -> FALSE
A5: SKU-0004 | B5: =_xlfn.XLOOKUP(A5,order_items!I:I,order_items!C:C) -> 4 | C5: =_xlfn.XLOOKUP(B5,inventory!B:B,inventory!D:D) -> 209 | D5: =SUMIFS(order_items!D:D,order_items!C:C,reorder_point!B5) -> 67 | E5: =450 -> 450 | F5: =ROUND(D5/E5,2) -> 0.15 | G5: =IFERROR(_xlfn.XLOOKUP(B5,purchase_orders!C:C,purchase_orders!L:L),"") -> 38 | H5: =IFERROR(F5*G5+10,"") -> 15.7 | I5: =IF(H5="","",IF(C5<H5,"Reorder","OK")) -> OK | J5: =COUNTIF(A5:A154,A5)>1 -> FALSE
A6: SKU-0005 | B6: =_xlfn.XLOOKUP(A6,order_items!I:I,order_items!C:C) -> 5 | C6: =_xlfn.XLOOKUP(B6,inventory!B:B,inventory!D:D) -> 400 | D6: =SUMIFS(order_items!D:D,order_items!C:C,reorder_point!B6) -> 16 | E6: =450 -> 450 | F6: =ROUND(D6/E6,2) -> 0.04 | G6: =IFERROR(_xlfn.XLOOKUP(B6,purchase_orders!C:C,purchase_orders!L:L),"") -> 27 | H6: =IFERROR(F6*G6+10,"") -> 11.08 | I6: =IF(H6="","",IF(C6<H6,"Reorder","OK")) -> OK | J6: =COUNTIF(A6:A155,A6)>1 -> FALSE
A7: SKU-0006 | B7: =_xlfn.XLOOKUP(A7,order_items!I:I,order_items!C:C) -> 6 | C7: =_xlfn.XLOOKUP(B7,inventory!B:B,inventory!D:D) -> 168 | D7: =SUMIFS(order_items!D:D,order_items!C:C,reorder_point!B7) -> 51 | E7: =450 -> 450 | F7: =ROUND(D7/E7,2) -> 0.11 | G7: =IFERROR(_xlfn.XLOOKUP(B7,purchase_orders!C:C,purchase_orders!L:L),"") -> 22 | H7: =IFERROR(F7*G7+10,"") -> 12.42 | I7: =IF(H7="","",IF(C7<H7,"Reorder","OK")) -> OK | J7: =COUNTIF(A7:A156,A7)>1 -> FALSE
A8: SKU-0007 | B8: =_xlfn.XLOOKUP(A8,order_items!I:I,order_items!C:C) -> 7 | C8: =_xlfn.XLOOKUP(B8,inventory!B:B,inventory!D:D) -> 316 | D8: =SUMIFS(order_items!D:D,order_items!C:C,reorder_point!B8) -> 26 | E8: =450 -> 450 | F8: =ROUND(D8/E8,2) -> 0.06 | G8: =IFERROR(_xlfn.XLOOKUP(B8,purchase_orders!C:C,purchase_orders!L:L),"") -> 58 | H8: =IFERROR(F8*G8+10,"") -> 13.48 | I8: =IF(H8="","",IF(C8<H8,"Reorder","OK")) -> OK | J8: =COUNTIF(A8:A157,A8)>1 -> FALSE
A9: SKU-0008 | B9: =_xlfn.XLOOKUP(A9,order_items!I:I,order_items!C:C) -> 8 | C9: =_xlfn.XLOOKUP(B9,inventory!B:B,inventory!D:D) -> 389 | D9: =SUMIFS(order_items!D:D,order_items!C:C,reorder_point!B9) -> 61 | E9: =450 -> 450 | F9: =ROUND(D9/E9,2) -> 0.14 | G9: =IFERROR(_xlfn.XLOOKUP(B9,purchase_orders!C:C,purchase_orders!L:L),"") -> 43 | H9: =IFERROR(F9*G9+10,"") -> 16.02 | I9: =IF(H9="","",IF(C9<H9,"Reorder","OK")) -> OK | J9: =COUNTIF(A9:A158,A9)>1 -> FALSE
A10: SKU-0009 | B10: =_xlfn.XLOOKUP(A10,order_items!I:I,order_items!C:C) -> 9 | C10: =_xlfn.XLOOKUP(B10,inventory!B:B,inventory!D:D) -> 183 | D10: =SUMIFS(order_items!D:D,order_items!C:C,reorder_point!B10) -> 31 | E10: =450 -> 450 | F10: =ROUND(D10/E10,2) -> 0.07 | G10: =IFERROR(_xlfn.XLOOKUP(B10,purchase_orders!C:C,purchase_orders!L:L),"") -> 54 | H10: =IFERROR(F10*G10+10,"") -> 13.78 | I10: =IF(H10="","",IF(C10<H10,"Reorder","OK")) -> OK | J10: =COUNTIF(A10:A159,A10)>1 -> FALSE
A11: SKU-0010 | B11: =_xlfn.XLOOKUP(A11,order_items!I:I,order_items!C:C) -> 10 | C11: =_xlfn.XLOOKUP(B11,inventory!B:B,inventory!D:D) -> 40 | D11: =SUMIFS(order_items!D:D,order_items!C:C,reorder_point!B11) -> 19 | E11: =450 -> 450 | F11: =ROUND(D11/E11,2) -> 0.04 | G11: =IFERROR(_xlfn.XLOOKUP(B11,purchase_orders!C:C,purchase_orders!L:L),"") -> 16 | H11: =IFERROR(F11*G11+10,"") -> 10.64 | I11: =IF(H11="","",IF(C11<H11,"Reorder","OK")) -> OK | J11: =COUNTIF(A11:A160,A11)>1 -> FALSE
A12: SKU-0011 | B12: =_xlfn.XLOOKUP(A12,order_items!I:I,order_items!C:C) -> 11 | C12: =_xlfn.XLOOKUP(B12,inventory!B:B,inventory!D:D) -> 130 | D12: =SUMIFS(order_items!D:D,order_items!C:C,reorder_point!B12) -> 3 | E12: =450 -> 450 | F12: =ROUND(D12/E12,2) -> 0.01 | G12: =IFERROR(_xlfn.XLOOKUP(B12,purchase_orders!C:C,purchase_orders!L:L),"") -> 48 | H12: =IFERROR(F12*G12+10,"") -> 10.48 | I12: =IF(H12="","",IF(C12<H12,"Reorder","OK")) -> OK | J12: =COUNTIF(A12:A161,A12)>1 -> FALSE
A13: SKU-0012 | B13: =_xlfn.XLOOKUP(A13,order_items!I:I,order_items!C:C) -> 12 | C13: =_xlfn.XLOOKUP(B13,inventory!B:B,inventory!D:D) -> 226 | D13: =SUMIFS(order_items!D:D,order_items!C:C,reorder_point!B13) -> 19 | E13: =450 -> 450 | F13: =ROUND(D13/E13,2) -> 0.04 | G13: =IFERROR(_xlfn.XLOOKUP(B13,purchase_orders!C:C,purchase_orders!L:L),"") -> 21 | H13: =IFERROR(F13*G13+10,"") -> 10.84 | I13: =IF(H13="","",IF(C13<H13,"Reorder","OK")) -> OK | J13: =COUNTIF(A13:A162,A13)>1 -> FALSE
A14: SKU-0013 | B14: =_xlfn.XLOOKUP(A14,order_items!I:I,order_items!C:C) -> 13 | C14: =_xlfn.XLOOKUP(B14,inventory!B:B,inventory!D:D) -> 436 | D14: =SUMIFS(order_items!D:D,order_items!C:C,reorder_point!B14) -> 34 | E14: =450 -> 450 | F14: =ROUND(D14/E14,2) -> 0.08 | G14: =IFERROR(_xlfn.XLOOKUP(B14,purchase_orders!C:C,purchase_orders!L:L),"") -> 33 | H14: =IFERROR(F14*G14+10,"") -> 12.64 | I14: =IF(H14="","",IF(C14<H14,"Reorder","OK")) -> OK | J14: =COUNTIF(A14:A163,A14)>1 -> FALSE
... A151: SKU-0150 | B151: =_xlfn.XLOOKUP(A151,order_items!I:I,order_items!C:C) -> 150 | C151: =_xlfn.XLOOKUP(B151,inventory!B:B,inventory!D:D) -> 387 | D151: =SUMIFS(order_items!D:D,order_items!C:C,reorder_point!B151) -> 27 | E151: =450 -> 450 | F151: =ROUND(D151/E151,2) -> 0.06 | G151: =IFERROR(_xlfn.XLOOKUP(B151,purchase_orders!C:C,purchase_orders!L:L),"") -> 19 | H151: =IFERROR(F151*G151+10,"") -> 11.14 | I151: =IF(H151="","",IF(C151<H151,"Reorder","OK")) -> OK | J151: =COUNTIF(A151:A300,A151)>1 -> FALSE

Sheet customer_orders
A1: order_id | B1: order_date | C1: customer_region | D1: sales_channel | E1: order_status | F1: month | G1: week
A2: 1001 | B2: 46045 | C2: East | D2: Amazon | E2: Shipped | F2: =TEXT(B2,"yyyy-mm") -> 2026-01 | G2: =YEAR(B2)&"-w"&TEXT(WEEKNUM(B2),"00") -> 2026-w04
A3: 1002 | B3: 46099 | C3: West | D3: Amazon | E3: Delivered | F3: =TEXT(B3,"yyyy-mm") -> 2026-03 | G3: =YEAR(B3)&"-w"&TEXT(WEEKNUM(B3),"00") -> 2026-w12
A4: 1003 | B4: 46126 | C4: South | D4: Amazon | E4: Backordered | F4: =TEXT(B4,"yyyy-mm") -> 2026-04 | G4: =YEAR(B4)&"-w"&TEXT(WEEKNUM(B4),"00") -> 2026-w16
A5: 1004 | B5: 46100 | C5: West | D5: Shopify | E5: Delivered | F5: =TEXT(B5,"yyyy-mm") -> 2026-03 | G5: =YEAR(B5)&"-w"&TEXT(WEEKNUM(B5),"00") -> 2026-w12
A6: 1005 | B6: 46098 | C6: East | D6: Amazon | E6: Cancelled | F6: =TEXT(B6,"yyyy-mm") -> 2026-03 | G6: =YEAR(B6)&"-w"&TEXT(WEEKNUM(B6),"00") -> 2026-w12
A7: 1006 | B7: 46043 | C7: West | D7: Walmart | E7: Delivered | F7: =TEXT(B7,"yyyy-mm") -> 2026-01 | G7: =YEAR(B7)&"-w"&TEXT(WEEKNUM(B7),"00") -> 2026-w04
A8: 1007 | B8: 46037 | C8: NULL | D8: Walmart | E8: Delivered | F8: =TEXT(B8,"yyyy-mm") -> 2026-01 | G8: =YEAR(B8)&"-w"&TEXT(WEEKNUM(B8),"00") -> 2026-w03
A9: 1008 | B9: 46120 | C9: Midwest | D9: Walmart | E9: Backordered | F9: =TEXT(B9,"yyyy-mm") -> 2026-04 | G9: =YEAR(B9)&"-w"&TEXT(WEEKNUM(B9),"00") -> 2026-w15
A10: 1009 | B10: 46099 | C10: NULL | D10: Shopify | E10: Backordered | F10: =TEXT(B10,"yyyy-mm") -> 2026-03 | G10: =YEAR(B10)&"-w"&TEXT(WEEKNUM(B10),"00") -> 2026-w12
A11: 1010 | B11: 46078 | C11: West | D11: Shopify | E11: Delivered | F11: =TEXT(B11,"yyyy-mm") -> 2026-02 | G11: =YEAR(B11)&"-w"&TEXT(WEEKNUM(B11),"00") -> 2026-w09
A12: 1011 | B12: 46104 | C12: Midwest | D12: Walmart | E12: Shipped | F12: =TEXT(B12,"yyyy-mm") -> 2026-03 | G12: =YEAR(B12)&"-w"&TEXT(WEEKNUM(B12),"00") -> 2026-w13
A13: 1012 | B13: 46085 | C13: South | D13: Shopify | E13: Cancelled | F13: =TEXT(B13,"yyyy-mm") -> 2026-03 | G13: =YEAR(B13)&"-w"&TEXT(WEEKNUM(B13),"00") -> 2026-w10
... A451: 1450 | B451: 46130 | C451: South | D451: Amazon | E451: Backordered | F451: =TEXT(B451,"yyyy-mm") -> 2026-04 | G451: =YEAR(B451)&"-w"&TEXT(WEEKNUM(B451),"00") -> 2026-w16

Sheet order_items
A1: order_item_id | B1: order_id | C1: product_id | D1: quantity | E1: unit_price | F1: discount_amount | G1: revenue | H1: month | I1: sku | J1: week | K1: freight_cost | L1: freight_pct | M1: sales_channel | N1: warehouse | O1: standard_cost | P1: margin | Q1: category
A2: 1 | B2: 1001 | C2: 45 | D2: 7 | E2: 184.44 | F2: 0 | G2: =E2*D2-F2 -> 1291.08 | H2: =_xlfn.XLOOKUP(B2,customer_orders!A:A,customer_orders!F:F) -> 2026-01 | I2: =_xlfn.XLOOKUP(C2,products!A:A,products!B:B) -> SKU-0045 | J2: =_xlfn.XLOOKUP(B2,customer_orders!A:A,customer_orders!G:G) -> 2026-w04 | K2: =IFERROR(_xlfn.XLOOKUP(B2,shipments!B:B,shipments!H:H),0) -> 25.61 | L2: =ROUND(K2/G2,2) -> 0.02 | M2: =_xlfn.XLOOKUP(B2,customer_orders!A:A,customer_orders!D:D) -> Amazon | N2: =_xlfn.XLOOKUP(C2,inventory!B:B,inventory!C:C) -> Draper | O2: =IF(_xlfn.XLOOKUP(C2,products!A:A,products!E:E)="NULL",0,_xlfn.XLOOKUP(C2,products!A:A,products!E:E)) -> 48.09 | P2: =G2-O2 -> 1242.99 | Q2: =_xlfn.XLOOKUP(I2,products!B:B,products!D:D) -> Home
A3: 2 | B3: 1002 | C3: 73 | D3: 8 | E3: 134.83 | F3: 14.85 | G3: =E3*D3-F3 -> 1063.79 | H3: =_xlfn.XLOOKUP(B3,customer_orders!A:A,customer_orders!F:F) -> 2026-03 | I3: =_xlfn.XLOOKUP(C3,products!A:A,products!B:B) -> SKU-0073 | J3: =_xlfn.XLOOKUP(B3,customer_orders!A:A,customer_orders!G:G) -> 2026-w12 | K3: =IFERROR(_xlfn.XLOOKUP(B3,shipments!B:B,shipments!H:H),0) -> 95.73 | L3: =ROUND(K3/G3,2) -> 0.09 | M3: =_xlfn.XLOOKUP(B3,customer_orders!A:A,customer_orders!D:D) -> Amazon | N3: =_xlfn.XLOOKUP(C3,inventory!B:B,inventory!C:C) -> Draper | O3: =IF(_xlfn.XLOOKUP(C3,products!A:A,products!E:E)="NULL",0,_xlfn.XLOOKUP(C3,products!A:A,products!E:E)) -> 27.28 | P3: =G3-O3 -> 1036.51 | Q3: =_xlfn.XLOOKUP(I3,products!B:B,products!D:D) -> Sports
A4: 3 | B4: 1002 | C4: 35 | D4: 8 | E4: 46.14 | F4: 0 | G4: =E4*D4-F4 -> 369.12 | H4: =_xlfn.XLOOKUP(B4,customer_orders!A:A,customer_orders!F:F) -> 2026-03 | I4: =_xlfn.XLOOKUP(C4,products!A:A,products!B:B) -> SKU-0035 | J4: =_xlfn.XLOOKUP(B4,customer_orders!A:A,customer_orders!G:G) -> 2026-w12 | K4: =IFERROR(_xlfn.XLOOKUP(B4,shipments!B:B,shipments!H:H),0) -> 95.73 | L4: =ROUND(K4/G4,2) -> 0.26 | M4: =_xlfn.XLOOKUP(B4,customer_orders!A:A,customer_orders!D:D) -> Amazon | N4: =_xlfn.XLOOKUP(C4,inventory!B:B,inventory!C:C) -> Salt Lake City | O4: =IF(_xlfn.XLOOKUP(C4,products!A:A,products!E:E)="NULL",0,_xlfn.XLOOKUP(C4,products!A:A,products!E:E)) -> 145.1 | P4: =G4-O4 -> 224.02 | Q4: =_xlfn.XLOOKUP(I4,products!B:B,products!D:D) -> Office
A5: 4 | B5: 1002 | C5: 85 | D5: 3 | E5: 163.57 | F5: 0 | G5: =E5*D5-F5 -> 490.71 | H5: =_xlfn.XLOOKUP(B5,customer_orders!A:A,customer_orders!F:F) -> 2026-03 | I5: =_xlfn.XLOOKUP(C5,products!A:A,products!B:B) -> SKU-0085 | J5: =_xlfn.XLOOKUP(B5,customer_orders!A:A,customer_orders!G:G) -> 2026-w12 | K5: =IFERROR(_xlfn.XLOOKUP(B5,shipments!B:B,shipments!H:H),0) -> 95.73 | L5: =ROUND(K5/G5,2) -> 0.2 | M5: =_xlfn.XLOOKUP(B5,customer_orders!A:A,customer_orders!D:D) -> Amazon | N5: =_xlfn.XLOOKUP(C5,inventory!B:B,inventory!C:C) -> Draper | O5: =IF(_xlfn.XLOOKUP(C5,products!A:A,products!E:E)="NULL",0,_xlfn.XLOOKUP(C5,products!A:A,products!E:E)) -> 139.02 | P5: =G5-O5 -> 351.69 | Q5: =_xlfn.XLOOKUP(I5,products!B:B,products!D:D) -> Beauty
A6: 5 | B6: 1003 | C6: 103 | D6: 2 | E6: 241.92 | F6: 0 | G6: =E6*D6-F6 -> 483.84 | H6: =_xlfn.XLOOKUP(B6,customer_orders!A:A,customer_orders!F:F) -> 2026-04 | I6: =_xlfn.XLOOKUP(C6,products!A:A,products!B:B) -> SKU-0103 | J6: =_xlfn.XLOOKUP(B6,customer_orders!A:A,customer_orders!G:G) -> 2026-w16 | K6: =IFERROR(_xlfn.XLOOKUP(B6,shipments!B:B,shipments!H:H),0) -> 4.79 | L6: =ROUND(K6/G6,2) -> 0.01 | M6: =_xlfn.XLOOKUP(B6,customer_orders!A:A,customer_orders!D:D) -> Amazon | N6: =_xlfn.XLOOKUP(C6,inventory!B:B,inventory!C:C) -> Draper | O6: =IF(_xlfn.XLOOKUP(C6,products!A:A,products!E:E)="NULL",0,_xlfn.XLOOKUP(C6,products!A:A,products!E:E)) -> 145.97 | P6: =G6-O6 -> 337.87 | Q6: =_xlfn.XLOOKUP(I6,products!B:B,products!D:D) -> Sports
A7: 6 | B7: 1004 | C7: 67 | D7: 6 | E7: 291.56 | F7: 0 | G7: =E7*D7-F7 -> 1749.36 | H7: =_xlfn.XLOOKUP(B7,customer_orders!A:A,customer_orders!F:F) -> 2026-03 | I7: =_xlfn.XLOOKUP(C7,products!A:A,products!B:B) -> SKU-0067 | J7: =_xlfn.XLOOKUP(B7,customer_orders!A:A,customer_orders!G:G) -> 2026-w12 | K7: =IFERROR(_xlfn.XLOOKUP(B7,shipments!B:B,shipments!H:H),0) -> 39.59 | L7: =ROUND(K7/G7,2) -> 0.02 | M7: =_xlfn.XLOOKUP(B7,customer_orders!A:A,customer_orders!D:D) -> Shopify | N7: =_xlfn.XLOOKUP(C7,inventory!B:B,inventory!C:C) -> West Valley | O7: =IF(_xlfn.XLOOKUP(C7,products!A:A,products!E:E)="NULL",0,_xlfn.XLOOKUP(C7,products!A:A,products!E:E)) -> 25.18 | P7: =G7-O7 -> 1724.18 | Q7: =_xlfn.XLOOKUP(I7,products!B:B,products!D:D) -> Kitchen
A8: 7 | B8: 1005 | C8: 35 | D8: 8 | E8: 46.14 | F8: 0 | G8: =E8*D8-F8 -> 369.12 | H8: =_xlfn.XLOOKUP(B8,customer_orders!A:A,customer_orders!F:F) -> 2026-03 | I8: =_xlfn.XLOOKUP(C8,products!A:A,products!B:B) -> SKU-0035 | J8: =_xlfn.XLOOKUP(B8,customer_orders!A:A,customer_orders!G:G) -> 2026-w12 | K8: =IFERROR(_xlfn.XLOOKUP(B8,shipments!B:B,shipments!H:H),0) -> 0 | L8: =ROUND(K8/G8,2) -> 0 | M8: =_xlfn.XLOOKUP(B8,customer_orders!A:A,customer_orders!D:D) -> Amazon | N8: =_xlfn.XLOOKUP(C8,inventory!B:B,inventory!C:C) -> Salt Lake City | O8: =IF(_xlfn.XLOOKUP(C8,products!A:A,products!E:E)="NULL",0,_xlfn.XLOOKUP(C8,products!A:A,products!E:E)) -> 145.1 | P8: =G8-O8 -> 224.02 | Q8: =_xlfn.XLOOKUP(I8,products!B:B,products!D:D) -> Office
A9: 8 | B9: 1005 | C9: 107 | D9: 8 | E9: 223.34 | F9: 0 | G9: =E9*D9-F9 -> 1786.72 | H9: =_xlfn.XLOOKUP(B9,customer_orders!A:A,customer_orders!F:F) -> 2026-03 | I9: =_xlfn.XLOOKUP(C9,products!A:A,products!B:B) -> SKU-0107 | J9: =_xlfn.XLOOKUP(B9,customer_orders!A:A,customer_orders!G:G) -> 2026-w12 | K9: =IFERROR(_xlfn.XLOOKUP(B9,shipments!B:B,shipments!H:H),0) -> 0 | L9: =ROUND(K9/G9,2) -> 0 | M9: =_xlfn.XLOOKUP(B9,customer_orders!A:A,customer_orders!D:D) -> Amazon | N9: =_xlfn.XLOOKUP(C9,inventory!B:B,inventory!C:C) -> South Jordan | O9: =IF(_xlfn.XLOOKUP(C9,products!A:A,products!E:E)="NULL",0,_xlfn.XLOOKUP(C9,products!A:A,products!E:E)) -> 81.23 | P9: =G9-O9 -> 1705.49 | Q9: =_xlfn.XLOOKUP(I9,products!B:B,products!D:D) -> Pet
A10: 9 | B10: 1006 | C10: 20 | D10: 2 | E10: 168.04 | F10: 0 | G10: =E10*D10-F10 -> 336.08 | H10: =_xlfn.XLOOKUP(B10,customer_orders!A:A,customer_orders!F:F) -> 2026-01 | I10: =_xlfn.XLOOKUP(C10,products!A:A,products!B:B) -> SKU-0020 | J10: =_xlfn.XLOOKUP(B10,customer_orders!A:A,customer_orders!G:G) -> 2026-w04 | K10: =IFERROR(_xlfn.XLOOKUP(B10,shipments!B:B,shipments!H:H),0) -> 97.81 | L10: =ROUND(K10/G10,2) -> 0.29 | M10: =_xlfn.XLOOKUP(B10,customer_orders!A:A,customer_orders!D:D) -> Walmart | N10: =_xlfn.XLOOKUP(C10,inventory!B:B,inventory!C:C) -> South Jordan | O10: =IF(_xlfn.XLOOKUP(C10,products!A:A,products!E:E)="NULL",0,_xlfn.XLOOKUP(C10,products!A:A,products!E:E)) -> 124.3 | P10: =G10-O10 -> 211.78 | Q10: =_xlfn.XLOOKUP(I10,products!B:B,products!D:D) -> Electronics
A11: 10 | B11: 1006 | C11: 147 | D11: 3 | E11: 133.41 | F11: 3.3 | G11: =E11*D11-F11 -> 396.93 | H11: =_xlfn.XLOOKUP(B11,customer_orders!A:A,customer_orders!F:F) -> 2026-01 | I11: =_xlfn.XLOOKUP(C11,products!A:A,products!B:B) -> SKU-0147 | J11: =_xlfn.XLOOKUP(B11,customer_orders!A:A,customer_orders!G:G) -> 2026-w04 | K11: =IFERROR(_xlfn.XLOOKUP(B11,shipments!B:B,shipments!H:H),0) -> 97.81 | L11: =ROUND(K11/G11,2) -> 0.25 | M11: =_xlfn.XLOOKUP(B11,customer_orders!A:A,customer_orders!D:D) -> Walmart | N11: =_xlfn.XLOOKUP(C11,inventory!B:B,inventory!C:C) -> Draper | O11: =IF(_xlfn.XLOOKUP(C11,products!A:A,products!E:E)="NULL",0,_xlfn.XLOOKUP(C11,products!A:A,products!E:E)) -> 128.45 | P11: =G11-O11 -> 268.48 | Q11: =_xlfn.XLOOKUP(I11,products!B:B,products!D:D) -> Sports
A12: 11 | B12: 1006 | C12: 30 | D12: 4 | E12: 35.23 | F12: 11.04 | G12: =E12*D12-F12 -> 129.88 | H12: =_xlfn.XLOOKUP(B12,customer_orders!A:A,customer_orders!F:F) -> 2026-01 | I12: =_xlfn.XLOOKUP(C12,products!A:A,products!B:B) -> SKU-0030 | J12: =_xlfn.XLOOKUP(B12,customer_orders!A:A,customer_orders!G:G) -> 2026-w04 | K12: =IFERROR(_xlfn.XLOOKUP(B12,shipments!B:B,shipments!H:H),0) -> 97.81 | L12: =ROUND(K12/G12,2) -> 0.75 | M12: =_xlfn.XLOOKUP(B12,customer_orders!A:A,customer_orders!D:D) -> Walmart | N12: =_xlfn.XLOOKUP(C12,inventory!B:B,inventory!C:C) -> Draper | O12: =IF(_xlfn.XLOOKUP(C12,products!A:A,products!E:E)="NULL",0,_xlfn.XLOOKUP(C12,products!A:A,products!E:E)) -> 43.54 | P12: =G12-O12 -> 86.34 | Q12: =_xlfn.XLOOKUP(I12,products!B:B,products!D:D) -> Beauty
A13: 12 | B13: 1007 | C13: 6 | D13: 7 | E13: 256.54 | F13: 0 | G13: =E13*D13-F13 -> 1795.78 | H13: =_xlfn.XLOOKUP(B13,customer_orders!A:A,customer_orders!F:F) -> 2026-01 | I13: =_xlfn.XLOOKUP(C13,products!A:A,products!B:B) -> SKU-0006 | J13: =_xlfn.XLOOKUP(B13,customer_orders!A:A,customer_orders!G:G) -> 2026-w03 | K13: =IFERROR(_xlfn.XLOOKUP(B13,shipments!B:B,shipments!H:H),0) -> 51.43 | L13: =ROUND(K13/G13,2) -> 0.03 | M13: =_xlfn.XLOOKUP(B13,customer_orders!A:A,customer_orders!D:D) -> Walmart | N13: =_xlfn.XLOOKUP(C13,inventory!B:B,inventory!C:C) -> South Jordan | O13: =IF(_xlfn.XLOOKUP(C13,products!A:A,products!E:E)="NULL",0,_xlfn.XLOOKUP(C13,products!A:A,products!E:E)) -> 21.93 | P13: =G13-O13 -> 1773.85 | Q13: =_xlfn.XLOOKUP(I13,products!B:B,products!D:D) -> Home
... A1109: 1108 | B1109: 1450 | C1109: 112 | D1109: 5 | E1109: 154.88 | F1109: 0 | G1109: =E1109*D1109-F1109 -> 774.4 | H1109: =_xlfn.XLOOKUP(B1109,customer_orders!A:A,customer_orders!F:F) -> 2026-04 | I1109: =_xlfn.XLOOKUP(C1109,products!A:A,products!B:B) -> SKU-0112 | J1109: =_xlfn.XLOOKUP(B1109,customer_orders!A:A,customer_orders!G:G) -> 2026-w16 | K1109: =IFERROR(_xlfn.XLOOKUP(B1109,shipments!B:B,shipments!H:H),0) -> 107.19 | L1109: =ROUND(K1109/G1109,2) -> 0.14 | M1109: =_xlfn.XLOOKUP(B1109,customer_orders!A:A,customer_orders!D:D) -> Amazon | N1109: =_xlfn.XLOOKUP(C1109,inventory!B:B,inventory!C:C) -> South Jordan | O1109: =IF(_xlfn.XLOOKUP(C1109,products!A:A,products!E:E)="NULL",0,_xlfn.XLOOKUP(C1109,products!A:A,products!E:E)) -> 118.03 | P1109: =G1109-O1109 -> 656.37 | Q1109: =_xlfn.XLOOKUP(I1109,products!B:B,products!D:D) -> Beauty

Sheet products
A1: product_id | B1: sku | C1: product_name | D1: category | E1: standard_cost | F1: selling_price | G1: supplier_id | H1: active_flag | I1: supplier_name | J1: quantity_on_hand | K1: total_cost | L1: units_sold | M1: Slow-moving
A2: 1 | B2: SKU-0001 | C2: Home Product 1 | D2: Home | E2: 134.77 | F2: 84.79 | G2: 3 | H2: N | I2: =_xlfn.XLOOKUP(G2,suppliers!A:A,suppliers!B:B) -> PrimeSource | J2: =IFERROR(_xlfn.XLOOKUP(A2,inventory!B:B,inventory!D:D),0) -> 22 | K2: =IFERROR(E2 * J2, 0) -> 2964.94 | L2: =SUMIFS(order_items!D:D,order_items!C:C,A2) -> 16 | M2: =IF(L2<10,"Slow Moving","Normal") -> Normal
A3: 2 | B3: SKU-0002 | C3: Home Product 2 | D3: Home | E3: 20.21 | F3: 135.25 | G3: 1 | H3: Y | I3: =_xlfn.XLOOKUP(G3,suppliers!A:A,suppliers!B:B) -> Acme Supply | J3: =IFERROR(_xlfn.XLOOKUP(A3,inventory!B:B,inventory!D:D),0) -> 405 | K3: =IFERROR(E3 * J3, 0) -> 8185.05 | L3: =SUMIFS(order_items!D:D,order_items!C:C,A3) -> 37 | M3: =IF(L3<10,"Slow Moving","Normal") -> Normal
A4: 3 | B4: SKU-0003 | C4: Beauty Product 3 | D4: Beauty | E4: 93.44 | F4: 22.56 | G4: 4 | H4: N | I4: =_xlfn.XLOOKUP(G4,suppliers!A:A,suppliers!B:B) -> Blue Ridge | J4: =IFERROR(_xlfn.XLOOKUP(A4,inventory!B:B,inventory!D:D),0) -> 51 | K4: =IFERROR(E4 * J4, 0) -> 4765.44 | L4: =SUMIFS(order_items!D:D,order_items!C:C,A4) -> 27 | M4: =IF(L4<10,"Slow Moving","Normal") -> Normal
A5: 4 | B5: SKU-0004 | C5: Office Product 4 | D5: Office | E5: 83.61 | F5: 94.28 | G5: 1 | H5: Unknown | I5: =_xlfn.XLOOKUP(G5,suppliers!A:A,suppliers!B:B) -> Acme Supply | J5: =IFERROR(_xlfn.XLOOKUP(A5,inventory!B:B,inventory!D:D),0) -> 209 | K5: =IFERROR(E5 * J5, 0) -> 17474.49 | L5: =SUMIFS(order_items!D:D,order_items!C:C,A5) -> 67 | M5: =IF(L5<10,"Slow Moving","Normal") -> Normal
A6: 5 | B6: SKU-0005 | C6: Toys Product 5 | D6: Toys | E6: 64.54 | F6: 59.31 | G6: 6 | H6: Y | I6: =_xlfn.XLOOKUP(G6,suppliers!A:A,suppliers!B:B) -> Evergreen Imports | J6: =IFERROR(_xlfn.XLOOKUP(A6,inventory!B:B,inventory!D:D),0) -> 400 | K6: =IFERROR(E6 * J6, 0) -> 25816 | L6: =SUMIFS(order_items!D:D,order_items!C:C,A6) -> 16 | M6: =IF(L6<10,"Slow Moving","Normal") -> Normal
A7: 6 | B7: SKU-0006 | C7: Home Product 6 | D7: Home | E7: 21.93 | F7: 256.54 | G7: 5 | H7: Unknown | I7: =_xlfn.XLOOKUP(G7,suppliers!A:A,suppliers!B:B) -> Utah Wholesale | J7: =IFERROR(_xlfn.XLOOKUP(A7,inventory!B:B,inventory!D:D),0) -> 168 | K7: =IFERROR(E7 * J7, 0) -> 3684.24 | L7: =SUMIFS(order_items!D:D,order_items!C:C,A7) -> 51 | M7: =IF(L7<10,"Slow Moving","Normal") -> Normal
A8: 7 | B8: SKU-0007 | C8: Electronics Product 7 | D8: Electronics | E8: 98.84 | F8: 292.34 | G8: 7 | H8: Y | I8: =_xlfn.XLOOKUP(G8,suppliers!A:A,suppliers!B:B) -> Summit Trading | J8: =IFERROR(_xlfn.XLOOKUP(A8,inventory!B:B,inventory!D:D),0) -> 316 | K8: =IFERROR(E8 * J8, 0) -> 31233.44 | L8: =SUMIFS(order_items!D:D,order_items!C:C,A8) -> 26 | M8: =IF(L8<10,"Slow Moving","Normal") -> Normal
A9: 8 | B9: SKU-0008 | C9: Sports Product 8 | D9: Sports | E9: 159.95 | F9: 118.07 | G9: 4 | H9: N | I9: =_xlfn.XLOOKUP(G9,suppliers!A:A,suppliers!B:B) -> Blue Ridge | J9: =IFERROR(_xlfn.XLOOKUP(A9,inventory!B:B,inventory!D:D),0) -> 389 | K9: =IFERROR(E9 * J9, 0) -> 62220.55 | L9: =SUMIFS(order_items!D:D,order_items!C:C,A9) -> 61 | M9: =IF(L9<10,"Slow Moving","Normal") -> Normal
A10: 9 | B10: SKU-0009 | C10: Home Product 9 | D10: Home | E10: 120.72 | F10: 235.32 | G10: 2 | H10: Unknown | I10: =_xlfn.XLOOKUP(G10,suppliers!A:A,suppliers!B:B) -> Global Goods | J10: =IFERROR(_xlfn.XLOOKUP(A10,inventory!B:B,inventory!D:D),0) -> 183 | K10: =IFERROR(E10 * J10, 0) -> 22091.76 | L10: =SUMIFS(order_items!D:D,order_items!C:C,A10) -> 31 | M10: =IF(L10<10,"Slow Moving","Normal") -> Normal
A11: 10 | B11: SKU-0010 | C11: Beauty Product 10 | D11: Beauty | E11: 71.52 | F11: 144.22 | G11: 6 | H11: N | I11: =_xlfn.XLOOKUP(G11,suppliers!A:A,suppliers!B:B) -> Evergreen Imports | J11: =IFERROR(_xlfn.XLOOKUP(A11,inventory!B:B,inventory!D:D),0) -> 40 | K11: =IFERROR(E11 * J11, 0) -> 2860.8 | L11: =SUMIFS(order_items!D:D,order_items!C:C,A11) -> 19 | M11: =IF(L11<10,"Slow Moving","Normal") -> Normal
A12: 11 | B12: SKU-0011 | C12: Kitchen Product 11 | D12: Kitchen | E12: 41.66 | F12: 91.09 | G12: 2 | H12: Y | I12: =_xlfn.XLOOKUP(G12,suppliers!A:A,suppliers!B:B) -> Global Goods | J12: =IFERROR(_xlfn.XLOOKUP(A12,inventory!B:B,inventory!D:D),0) -> 130 | K12: =IFERROR(E12 * J12, 0) -> 5415.8 | L12: =SUMIFS(order_items!D:D,order_items!C:C,A12) -> 3 | M12: =IF(L12<10,"Slow Moving","Normal") -> Slow Moving
A13: 12 | B13: SKU-0012 | C13: Toys Product 12 | D13: Toys | E13: 132.6 | F13: 61.57 | G13: 7 | H13: Y | I13: =_xlfn.XLOOKUP(G13,suppliers!A:A,suppliers!B:B) -> Summit Trading | J13: =IFERROR(_xlfn.XLOOKUP(A13,inventory!B:B,inventory!D:D),0) -> 226 | K13: =IFERROR(E13 * J13, 0) -> 29967.6 | L13: =SUMIFS(order_items!D:D,order_items!C:C,A13) -> 19 | M13: =IF(L13<10,"Slow Moving","Normal") -> Normal
... A53: 52 | B53: SKU-0052 | C53: Home Product 52 | D53: Home | E53: 134.92 | F53: 59.3 | G53: 5 | H53: Y | I53: =_xlfn.XLOOKUP(G53,suppliers!A:A,suppliers!B:B) -> Utah Wholesale | J53: =IFERROR(_xlfn.XLOOKUP(A53,inventory!B:B,inventory!D:D),0) -> 0 | K53: =IFERROR(E53 * J53, 0) -> 0 | L53: =SUMIFS(order_items!D:D,order_items!C:C,A53) -> 55 | M53: =IF(L53<10,"Slow Moving","Normal") -> Normal
A54: 53 | B54: SKU-0053 | C54: Beauty Product 53 | D54: Beauty | E54: NULL | F54: 73.03 | G54: 5 | H54: Y | I54: =_xlfn.XLOOKUP(G54,suppliers!A:A,suppliers!B:B) -> Utah Wholesale | J54: =IFERROR(_xlfn.XLOOKUP(A54,inventory!B:B,inventory!D:D),0) -> 286 | K54: =IFERROR(E54 * J54, 0) -> 0 | L54: =SUMIFS(order_items!D:D,order_items!C:C,A54) -> 19 | M54: =IF(L54<10,"Slow Moving","Normal") -> Normal
A55: 54 | B55: SKU-0054 | C55: Pet Product 54 | D55: Pet | E55: 163.43 | F55: 256.14 | G55: 2 | H55: N | I55: =_xlfn.XLOOKUP(G55,suppliers!A:A,suppliers!B:B) -> Global Goods | J55: =IFERROR(_xlfn.XLOOKUP(A55,inventory!B:B,inventory!D:D),0) -> 441 | K55: =IFERROR(E55 * J55, 0) -> 72072.63 | L55: =SUMIFS(order_items!D:D,order_items!C:C,A55) -> 11 | M55: =IF(L55<10,"Slow Moving","Normal") -> Normal
A56: 55 | B56: SKU-0055 | C56: Office Product 55 | D56: Office | E56: 12.72 | F56: 110.06 | G56: 3 | H56: N | I56: =_xlfn.XLOOKUP(G56,suppliers!A:A,suppliers!B:B) -> PrimeSource | J56: =IFERROR(_xlfn.XLOOKUP(A56,inventory!B:B,inventory!D:D),0) -> 363 | K56: =IFERROR(E56 * J56, 0) -> 4617.36 | L56: =SUMIFS(order_items!D:D,order_items!C:C,A56) -> 24 | M56: =IF(L56<10,"Slow Moving","Normal") -> Normal
A57: 56 | B57: SKU-0056 | C57: Sports Product 56 | D57: Sports | E57: 134.72 | F57: 172.23 | G57: 7 | H57: Y | I57: =_xlfn.XLOOKUP(G57,suppliers!A:A,suppliers!B:B) -> Summit Trading | J57: =IFERROR(_xlfn.XLOOKUP(A57,inventory!B:B,inventory!D:D),0) -> 425 | K57: =IFERROR(E57 * J57, 0) -> 57256 | L57: =SUMIFS(order_items!D:D,order_items!C:C,A57) -> 28 | M57: =IF(L57<10,"Slow Moving","Normal") -> Normal
A58: 57 | B58: SKU-0057 | C58: Electronics Product 57 | D58: Electronics | E58: 18.17 | F58: 266.69 | G58: 3 | H58: Y | I58: =_xlfn.XLOOKUP(G58,suppliers!A:A,suppliers!B:B) -> PrimeSource | J58: =IFERROR(_xlfn.XLOOKUP(A58,inventory!B:B,inventory!D:D),0) -> 432 | K58: =IFERROR(E58 * J58, 0) -> 7849.44 | L58: =SUMIFS(order_items!D:D,order_items!C:C,A58) -> 34 | M58: =IF(L58<10,"Slow Moving","Normal") -> Normal
A59: 58 | B59: SKU-0058 | C59: Electronics Product 58 | D59: Electronics | E59: 106.94 | F59: 57.21 | G59: 3 | H59: Y | I59: =_xlfn.XLOOKUP(G59,suppliers!A:A,suppliers!B:B) -> PrimeSource | J59: =IFERROR(_xlfn.XLOOKUP(A59,inventory!B:B,inventory!D:D),0) -> 445 | K59: =IFERROR(E59 * J59, 0) -> 47588.3 | L59: =SUMIFS(order_items!D:D,order_items!C:C,A59) -> 16 | M59: =IF(L59<10,"Slow Moving","Normal") -> Normal
A60: 59 | B60: SKU-0059 | C60: Sports Product 59 | D60: Sports | E60: 162.32 | F60: 0 | G60: 1 | H60: Y | I60: =_xlfn.XLOOKUP(G60,suppliers!A:A,suppliers!B:B) -> Acme Supply | J60: =IFERROR(_xlfn.XLOOKUP(A60,inventory!B:B,inventory!D:D),0) -> 178 | K60: =IFERROR(E60 * J60, 0) -> 28892.96 | L60: =SUMIFS(order_items!D:D,order_items!C:C,A60) -> 17 | M60: =IF(L60<10,"Slow Moving","Normal") -> Normal
A61: 60 | B61: SKU-0060 | C61: Beauty Product 60 | D61: Beauty | E61: 121.71 | F61: 115.8 | G61: 7 | H61: Y | I61: =_xlfn.XLOOKUP(G61,suppliers!A:A,suppliers!B:B) -> Summit Trading | J61: =IFERROR(_xlfn.XLOOKUP(A61,inventory!B:B,inventory!D:D),0) -> 389 | K61: =IFERROR(E61 * J61, 0) -> 47345.19 | L61: =SUMIFS(order_items!D:D,order_items!C:C,A61) -> 31 | M61: =IF(L61<10,"Slow Moving","Normal") -> Normal
A62: 61 | B62: SKU-0061 | C62: Toys Product 61 | D62: Toys | E62: 156.31 | F62: 293.22 | G62: 3 | H62: N | I62: =_xlfn.XLOOKUP(G62,suppliers!A:A,suppliers!B:B) -> PrimeSource | J62: =IFERROR(_xlfn.XLOOKUP(A62,inventory!B:B,inventory!D:D),0) -> 237 | K62: =IFERROR(E62 * J62, 0) -> 37045.47 | L62: =SUMIFS(order_items!D:D,order_items!C:C,A62) -> 43 | M62: =IF(L62<10,"Slow Moving","Normal") -> Normal
A63: 62 | B63: SKU-0062 | C63: Electronics Product 62 | D63: Electronics | E63: 133.9 | F63: 109.67 | G63: 7 | H63: Unknown | I63: =_xlfn.XLOOKUP(G63,suppliers!A:A,suppliers!B:B) -> Summit Trading | J63: =IFERROR(_xlfn.XLOOKUP(A63,inventory!B:B,inventory!D:D),0) -> 497 | K63: =IFERROR(E63 * J63, 0) -> 66548.3 | L63: =SUMIFS(order_items!D:D,order_items!C:C,A63) -> 18 | M63: =IF(L63<10,"Slow Moving","Normal") -> Normal
A64: 63 | B64: SKU-0063 | C64: Beauty Product 63 | D64: Beauty | E64: 32.86 | F64: 214.86 | G64: 7 | H64: Unknown | I64: =_xlfn.XLOOKUP(G64,suppliers!A:A,suppliers!B:B) -> Summit Trading | J64: =IFERROR(_xlfn.XLOOKUP(A64,inventory!B:B,inventory!D:D),0) -> 37 | K64: =IFERROR(E64 * J64, 0) -> 1215.82 | L64: =SUMIFS(order_items!D:D,order_items!C:C,A64) -> 31 | M64: =IF(L64<10,"Slow Moving","Normal") -> Normal
A65: 64 | B65: SKU-0064 | C65: Electronics Product 64 | D65: Electronics | E65: 43.93 | F65: 247.73 | G65: 8 | H65: Y | I65: =_xlfn.XLOOKUP(G65,suppliers!A:A,suppliers!B:B) -> Metro Logistics | J65: =IFERROR(_xlfn.XLOOKUP(A65,inventory!B:B,inventory!D:D),0) -> 196 | K65: =IFERROR(E65 * J65, 0) -> 8610.28 | L65: =SUMIFS(order_items!D:D,order_items!C:C,A65) -> 18 | M65: =IF(L65<10,"Slow Moving","Normal") -> Normal
A66: 65 | B66: SKU-0065 | C66: Sports Product 65 | D66: Sports | E66: 44.01 | F66: 203.11 | G66: 7 | H66: Y | I66: =_xlfn.XLOOKUP(G66,suppliers!A:A,suppliers!B:B) -> Summit Trading | J66: =IFERROR(_xlfn.XLOOKUP(A66,inventory!B:B,inventory!D:D),0) -> 292 | K66: =IFERROR(E66 * J66, 0) -> 12850.92 | L66: =SUMIFS(order_items!D:D,order_items!C:C,A66) -> 12 | M66: =IF(L66<10,"Slow Moving","Normal") -> Normal
... A106: 105 | B106: SKU-0105 | C106: Office Product 105 | D106: Office | E106: 23.47 | F106: 288.82 | G106: 8 | H106: N | I106: =_xlfn.XLOOKUP(G106,suppliers!A:A,suppliers!B:B) -> Metro Logistics | J106: =IFERROR(_xlfn.XLOOKUP(A106,inventory!B:B,inventory!D:D),0) -> 390 | K106: =IFERROR(E106 * J106, 0) -> 9153.3 | L106: =SUMIFS(order_items!D:D,order_items!C:C,A106) -> 14 | M106: =IF(L106<10,"Slow Moving","Normal") -> Normal
A107: 106 | B107: SKU-0106 | C107: Toys Product 106 | D107: Toys | E107: NULL | F107: 65.2 | G107: 5 | H107: Y | I107: =_xlfn.XLOOKUP(G107,suppliers!A:A,suppliers!B:B) -> Utah Wholesale | J107: =IFERROR(_xlfn.XLOOKUP(A107,inventory!B:B,inventory!D:D),0) -> 13 | K107: =IFERROR(E107 * J107, 0) -> 0 | L107: =SUMIFS(order_items!D:D,order_items!C:C,A107) -> 34 | M107: =IF(L107<10,"Slow Moving","Normal") -> Normal
A108: 107 | B108: SKU-0107 | C108: Pet Product 107 | D108: Pet | E108: 81.23 | F108: 223.34 | G108: 5 | H108: Y | I108: =_xlfn.XLOOKUP(G108,suppliers!A:A,suppliers!B:B) -> Utah Wholesale | J108: =IFERROR(_xlfn.XLOOKUP(A108,inventory!B:B,inventory!D:D),0) -> 146 | K108: =IFERROR(E108 * J108, 0) -> 11859.58 | L108: =SUMIFS(order_items!D:D,order_items!C:C,A108) -> 46 | M108: =IF(L108<10,"Slow Moving","Normal") -> Normal
A109: 108 | B109: SKU-0108 | C109: Beauty Product 108 | D109: Beauty | E109: 53.81 | F109: 143.48 | G109: 8 | H109: Y | I109: =_xlfn.XLOOKUP(G109,suppliers!A:A,suppliers!B:B) -> Metro Logistics | J109: =IFERROR(_xlfn.XLOOKUP(A109,inventory!B:B,inventory!D:D),0) -> 349 | K109: =IFERROR(E109 * J109, 0) -> 18779.69 | L109: =SUMIFS(order_items!D:D,order_items!C:C,A109) -> 37 | M109: =IF(L109<10,"Slow Moving","Normal") -> Normal
A110: 109 | B110: SKU-0109 | C110: Office Product 109 | D110: Office | E110: 10.02 | F110: 257.52 | G110: 3 | H110: N | I110: =_xlfn.XLOOKUP(G110,suppliers!A:A,suppliers!B:B) -> PrimeSource | J110: =IFERROR(_xlfn.XLOOKUP(A110,inventory!B:B,inventory!D:D),0) -> 406 | K110: =IFERROR(E110 * J110, 0) -> 4068.12 | L110: =SUMIFS(order_items!D:D,order_items!C:C,A110) -> 56 | M110: =IF(L110<10,"Slow Moving","Normal") -> Normal
A111: 110 | B111: SKU-0110 | C111: Beauty Product 110 | D111: Beauty | E111: 144.62 | F111: 112 | G111: 5 | H111: Y | I111: =_xlfn.XLOOKUP(G111,suppliers!A:A,suppliers!B:B) -> Utah Wholesale | J111: =IFERROR(_xlfn.XLOOKUP(A111,inventory!B:B,inventory!D:D),0) -> 404 | K111: =IFERROR(E111 * J111, 0) -> 58426.48 | L111: =SUMIFS(order_items!D:D,order_items!C:C,A111) -> 38 | M111: =IF(L111<10,"Slow Moving","Normal") -> Normal
A112: 111 | B112: SKU0111 | C112: Electronics Product 111 | D112: Electronics | E112: 170.91 | F112: 39.4 | G112: 7 | H112: N | I112: =_xlfn.XLOOKUP(G112,suppliers!A:A,suppliers!B:B) -> Summit Trading | J112: =IFERROR(_xlfn.XLOOKUP(A112,inventory!B:B,inventory!D:D),0) -> 282 | K112: =IFERROR(E112 * J112, 0) -> 48196.62 | L112: =SUMIFS(order_items!D:D,order_items!C:C,A112) -> 22 | M112: =IF(L112<10,"Slow Moving","Normal") -> Normal
A113: 112 | B113: SKU-0112 | C113: Beauty Product 112 | D113: Beauty | E113: 118.03 | F113: 154.88 | G113: 1 | H113: Y | I113: =_xlfn.XLOOKUP(G113,suppliers!A:A,suppliers!B:B) -> Acme Supply | J113: =IFERROR(_xlfn.XLOOKUP(A113,inventory!B:B,inventory!D:D),0) -> 64 | K113: =IFERROR(E113 * J113, 0) -> 7553.92 | L113: =SUMIFS(order_items!D:D,order_items!C:C,A113) -> 41 | M113: =IF(L113<10,"Slow Moving","Normal") -> Normal
A114: 113 | B114: SKU-0113 | C114: Sports Product 113 | D114: Sports | E114: 75.77 | F114: 84.34 | G114: 6 | H114: N | I114: =_xlfn.XLOOKUP(G114,suppliers!A:A,suppliers!B:B) -> Evergreen Imports | J114: =IFERROR(_xlfn.XLOOKUP(A114,inventory!B:B,inventory!D:D),0) -> 399 | K114: =IFERROR(E114 * J114, 0) -> 30232.23 | L114: =SUMIFS(order_items!D:D,order_items!C:C,A114) -> 21 | M114: =IF(L114<10,"Slow Moving","Normal") -> Normal
A115: 114 | B115: SKU-0114 | C115: Kitchen Product 114 | D115: Kitchen | E115: 179.41 | F115: 171.86 | G115: 6 | H115: N | I115: =_xlfn.XLOOKUP(G115,suppliers!A:A,suppliers!B:B) -> Evergreen Imports | J115: =IFERROR(_xlfn.XLOOKUP(A115,inventory!B:B,inventory!D:D),0) -> 265 | K115: =IFERROR(E115 * J115, 0) -> 47543.65 | L115: =SUMIFS(order_items!D:D,order_items!C:C,A115) -> 25 | M115: =IF(L115<10,"Slow Moving","Normal") -> Normal
A116: 115 | B116: SKU-0115 | C116: Pet Product 115 | D116: Pet | E116: 58.66 | F116: 80.7 | G116: 4 | H116: Y | I116: =_xlfn.XLOOKUP(G116,suppliers!A:A,suppliers!B:B) -> Blue Ridge | J116: =IFERROR(_xlfn.XLOOKUP(A116,inventory!B:B,inventory!D:D),0) -> 478 | K116: =IFERROR(E116 * J116, 0) -> 28039.48 | L116: =SUMIFS(order_items!D:D,order_items!C:C,A116) -> 22 | M116: =IF(L116<10,"Slow Moving","Normal") -> Normal
A117: 116 | B117: SKU-0116 | C117: Home Product 116 | D117: Home | E117: 171.4 | F117: 211.7 | G117: 4 | H117: N | I117: =_xlfn.XLOOKUP(G117,suppliers!A:A,suppliers!B:B) -> Blue Ridge | J117: =IFERROR(_xlfn.XLOOKUP(A117,inventory!B:B,inventory!D:D),0) -> 100 | K117: =IFERROR(E117 * J117, 0) -> 17140 | L117: =SUMIFS(order_items!D:D,order_items!C:C,A117) -> 14 | M117: =IF(L117<10,"Slow Moving","Normal") -> Normal
A118: 117 | B118: SKU-0117 | C118: Pet Product 117 | D118: Pet | E118: 131.8 | F118: 293.33 | G118: 5 | H118: Y | I118: =_xlfn.XLOOKUP(G118,suppliers!A:A,suppliers!B:B) -> Utah Wholesale | J118: =IFERROR(_xlfn.XLOOKUP(A118,inventory!B:B,inventory!D:D),0) -> 337 | K118: =IFERROR(E118 * J118, 0) -> 44416.6 | L118: =SUMIFS(order_items!D:D,order_items!C:C,A118) -> 55 | M118: =IF(L118<10,"Slow Moving","Normal") -> Normal
...

Sheet inventory
A1: inventory_id | B1: product_id | C1: warehouse | D1: quantity_on_hand | E1: last_updated | F1: received_date | G1: days_on_hand | H1: days_old | I1: units_sold | J1: overstock_status | K1: received_qty | L1: avg_inventory | M1: inventory_turnover | N1: standard_cost | O1: inventory_value | P1: slow_moving | Q1: Stockout_risk | R1: SKU
A2: 1 | B2: 1 | C2: South Jordan | D2: 22 | E2: 46113 | F2: =_xlfn.XLOOKUP(B2,purchase_orders!C:C,purchase_orders!G:G) -> 46092 | G2: =TODAY()-F2 -> 72 | H2: =IF(G2<=30,"0-30",IF(G2<=60,"31-60",IF(G2<=90,"61-90","90+"))) -> 61-90 | I2: =SUMIFS(order_items!D:D,order_items!C:C,inventory!B2) -> 16 | J2: =IF(D2>I2*3,"Overstock","OK") -> OK | K2: =IFERROR(_xlfn.XLOOKUP(B2,purchase_orders!C:C,purchase_orders!I:I),0) -> 619 | L2: =(D2+K2)/2 -> 320.5 | M2: =IFERROR(ROUND(I2/L2,2),0) -> 0.05 | N2: =IFERROR(_xlfn.XLOOKUP(B2,products!A:A,products!E:E),0) -> 134.77 | O2: =IF(N2="NULL",0,N2*D2) -> 2964.94 | P2: =IF(I2<10,"Slow Moving","Normal") -> Normal | Q2: =IFERROR(_xlfn.XLOOKUP(B2,reorder_point!B:B,reorder_point!I:I),"") -> OK | R2: =_xlfn.XLOOKUP(B2,products!A:A,products!B:B) -> SKU-0001
A3: 2 | B3: 2 | C3: South Jordan | D3: 405 | E3: 46134 | F3: =_xlfn.XLOOKUP(B3,purchase_orders!C:C,purchase_orders!G:G) -> 46175 | G3: =TODAY()-F3 -> -11 | H3: =IF(G3<=30,"0-30",IF(G3<=60,"31-60",IF(G3<=90,"61-90","90+"))) -> 0-30 | I3: =SUMIFS(order_items!D:D,order_items!C:C,inventory!B3) -> 37 | J3: =IF(D3>I3*3,"Overstock","OK") -> Overstock | K3: =IFERROR(_xlfn.XLOOKUP(B3,purchase_orders!C:C,purchase_orders!I:I),0) -> 919 | L3: =(D3+K3)/2 -> 662 | M3: =IFERROR(ROUND(I3/L3,2),0) -> 0.06 | N3: =IFERROR(_xlfn.XLOOKUP(B3,products!A:A,products!E:E),0) -> 20.21 | O3: =IF(N3="NULL",0,N3*D3) -> 8185.05 | P3: =IF(I3<10,"Slow Moving","Normal") -> Normal | Q3: =IFERROR(_xlfn.XLOOKUP(B3,reorder_point!B:B,reorder_point!I:I),"") -> OK | R3: =_xlfn.XLOOKUP(B3,products!A:A,products!B:B) -> SKU-0002
A4: 3 | B4: 2 | C4: Unknown | D4: 253 | E4: 46135 | F4: =_xlfn.XLOOKUP(B4,purchase_orders!C:C,purchase_orders!G:G) -> 46175 | G4: =TODAY()-F4 -> -11 | H4: =IF(G4<=30,"0-30",IF(G4<=60,"31-60",IF(G4<=90,"61-90","90+"))) -> 0-30 | I4: =SUMIFS(order_items!D:D,order_items!C:C,inventory!B4) -> 37 | J4: =IF(D4>I4*3,"Overstock","OK") -> Overstock | K4: =IFERROR(_xlfn.XLOOKUP(B4,purchase_orders!C:C,purchase_orders!I:I),0) -> 919 | L4: =(D4+K4)/2 -> 586 | M4: =IFERROR(ROUND(I4/L4,2),0) -> 0.06 | N4: =IFERROR(_xlfn.XLOOKUP(B4,products!A:A,products!E:E),0) -> 20.21 | O4: =IF(N4="NULL",0,N4*D4) -> 5113.13 | P4: =IF(I4<10,"Slow Moving","Normal") -> Normal | Q4: =IFERROR(_xlfn.XLOOKUP(B4,reorder_point!B:B,reorder_point!I:I),"") -> OK | R4: =_xlfn.XLOOKUP(B4,products!A:A,products!B:B) -> SKU-0002
A5: 4 | B5: 2 | C5: West Valley | D5: 257 | E5: 46122 | F5: =_xlfn.XLOOKUP(B5,purchase_orders!C:C,purchase_orders!G:G) -> 46175 | G5: =TODAY()-F5 -> -11 | H5: =IF(G5<=30,"0-30",IF(G5<=60,"31-60",IF(G5<=90,"61-90","90+"))) -> 0-30 | I5: =SUMIFS(order_items!D:D,order_items!C:C,inventory!B5) -> 37 | J5: =IF(D5>I5*3,"Overstock","OK") -> Overstock | K5: =IFERROR(_xlfn.XLOOKUP(B5,purchase_orders!C:C,purchase_orders!I:I),0) -> 919 | L5: =(D5+K5)/2 -> 588 | M5: =IFERROR(ROUND(I5/L5,2),0) -> 0.06 | N5: =IFERROR(_xlfn.XLOOKUP(B5,products!A:A,products!E:E),0) -> 20.21 | O5: =IF(N5="NULL",0,N5*D5) -> 5193.97 | P5: =IF(I5<10,"Slow Moving","Normal") -> Normal | Q5: =IFERROR(_xlfn.XLOOKUP(B5,reorder_point!B:B,reorder_point!I:I),"") -> OK | R5: =_xlfn.XLOOKUP(B5,products!A:A,products!B:B) -> SKU-0002
A6: 5 | B6: 3 | C6: South Jordan | D6: 51 | E6: 46114 | F6: =_xlfn.XLOOKUP(B6,purchase_orders!C:C,purchase_orders!G:G) -> 46077 | G6: =TODAY()-F6 -> 87 | H6: =IF(G6<=30,"0-30",IF(G6<=60,"31-60",IF(G6<=90,"61-90","90+"))) -> 61-90 | I6: =SUMIFS(order_items!D:D,order_items!C:C,inventory!B6) -> 27 | J6: =IF(D6>I6*3,"Overstock","OK") -> OK | K6: =IFERROR(_xlfn.XLOOKUP(B6,purchase_orders!C:C,purchase_orders!I:I),0) -> 760 | L6: =(D6+K6)/2 -> 405.5 | M6: =IFERROR(ROUND(I6/L6,2),0) -> 0.07 | N6: =IFERROR(_xlfn.XLOOKUP(B6,products!A:A,products!E:E),0) -> 93.44 | O6: =IF(N6="NULL",0,N6*D6) -> 4765.44 | P6: =IF(I6<10,"Slow Moving","Normal") -> Normal | Q6: =IFERROR(_xlfn.XLOOKUP(B6,reorder_point!B:B,reorder_point!I:I),"") -> OK | R6: =_xlfn.XLOOKUP(B6,products!A:A,products!B:B) -> SKU-0003
A7: 6 | B7: 4 | C7: Draper | D7: 209 | E7: 46134 | F7: =_xlfn.XLOOKUP(B7,purchase_orders!C:C,purchase_orders!G:G) -> 46072 | G7: =TODAY()-F7 -> 92 | H7: =IF(G7<=30,"0-30",IF(G7<=60,"31-60",IF(G7<=90,"61-90","90+"))) -> 90+ | I7: =SUMIFS(order_items!D:D,order_items!C:C,inventory!B7) -> 67 | J7: =IF(D7>I7*3,"Overstock","OK") -> Overstock | K7: =IFERROR(_xlfn.XLOOKUP(B7,purchase_orders!C:C,purchase_orders!I:I),0) -> 382 | L7: =(D7+K7)/2 -> 295.5 | M7: =IFERROR(ROUND(I7/L7,2),0) -> 0.23 | N7: =IFERROR(_xlfn.XLOOKUP(B7,products!A:A,products!E:E),0) -> 83.61 | O7: =IF(N7="NULL",0,N7*D7) -> 17474.49 | P7: =IF(I7<10,"Slow Moving","Normal") -> Normal | Q7: =IFERROR(_xlfn.XLOOKUP(B7,reorder_point!B:B,reorder_point!I:I),"") -> OK | R7: =_xlfn.XLOOKUP(B7,products!A:A,products!B:B) -> SKU-0004
A8: 7 | B8: 5 | C8: South Jordan | D8: 400 | E8: 46122 | F8: =_xlfn.XLOOKUP(B8,purchase_orders!C:C,purchase_orders!G:G) -> 46105 | G8: =TODAY()-F8 -> 59 | H8: =IF(G8<=30,"0-30",IF(G8<=60,"31-60",IF(G8<=90,"61-90","90+"))) -> 31-60 | I8: =SUMIFS(order_items!D:D,order_items!C:C,inventory!B8) -> 16 | J8: =IF(D8>I8*3,"Overstock","OK") -> Overstock | K8: =IFERROR(_xlfn.XLOOKUP(B8,purchase_orders!C:C,purchase_orders!I:I),0) -> 914 | L8: =(D8+K8)/2 -> 657 | M8: =IFERROR(ROUND(I8/L8,2),0) -> 0.02 | N8: =IFERROR(_xlfn.XLOOKUP(B8,products!A:A,products!E:E),0) -> 64.54 | O8: =IF(N8="NULL",0,N8*D8) -> 25816 | P8: =IF(I8<10,"Slow Moving","Normal") -> Normal | Q8: =IFERROR(_xlfn.XLOOKUP(B8,reorder_point!B:B,reorder_point!I:I),"") -> OK | R8: =_xlfn.XLOOKUP(B8,products!A:A,products!B:B) -> SKU-0005
A9: 8 | B9: 6 | C9: South Jordan | D9: 168 | E9: 46089 | F9: =_xlfn.XLOOKUP(B9,purchase_orders!C:C,purchase_orders!G:G) -> 46050 | G9: =TODAY()-F9 -> 114 | H9: =IF(G9<=30,"0-30",IF(G9<=60,"31-60",IF(G9<=90,"61-90","90+"))) -> 90+ | I9: =SUMIFS(order_items!D:D,order_items!C:C,inventory!B9) -> 51 | J9: =IF(D9>I9*3,"Overstock","OK") -> Overstock | K9: =IFERROR(_xlfn.XLOOKUP(B9,purchase_orders!C:C,purchase_orders!I:I),0) -> 392 | L9: =(D9+K9)/2 -> 280 | M9: =IFERROR(ROUND(I9/L9,2),0) -> 0.18 | N9: =IFERROR(_xlfn.XLOOKUP(B9,products!A:A,products!E:E),0) -> 21.93 | O9: =IF(N9="NULL",0,N9*D9) -> 3684.24 | P9: =IF(I9<10,"Slow Moving","Normal") -> Normal | Q9: =IFERROR(_xlfn.XLOOKUP(B9,reorder_point!B:B,reorder_point!I:I),"") -> OK | R9: =_xlfn.XLOOKUP(B9,products!A:A,products!B:B) -> SKU-0006
A10: 9 | B10: 6 | C10: Salt Lake City | D10: 273 | E10: 46123 | F10: =_xlfn.XLOOKUP(B10,purchase_orders!C:C,purchase_orders!G:G) -> 46050 | G10: =TODAY()-F10 -> 114 | H10: =IF(G10<=30,"0-30",IF(G10<=60,"31-60",IF(G10<=90,"61-90","90+"))) -> 90+ | I10: =SUMIFS(order_items!D:D,order_items!C:C,inventory!B10) -> 51 | J10: =IF(D10>I10*3,"Overstock","OK") -> Overstock | K10: =IFERROR(_xlfn.XLOOKUP(B10,purchase_orders!C:C,purchase_orders!I:I),0) -> 392 | L10: =(D10+K10)/2 -> 332.5 | M10: =IFERROR(ROUND(I10/L10,2),0) -> 0.15 | N10: =IFERROR(_xlfn.XLOOKUP(B10,products!A:A,products!E:E),0) -> 21.93 | O10: =IF(N10="NULL",0,N10*D10) -> 5986.89 | P10: =IF(I10<10,"Slow Moving","Normal") -> Normal | Q10: =IFERROR(_xlfn.XLOOKUP(B10,reorder_point!B:B,reorder_point!I:I),"") -> OK | R10: =_xlfn.XLOOKUP(B10,products!A:A,products!B:B) -> SKU-0006
A11: 10 | B11: 6 | C11: Unknown | D11: 320 | E11: 46095 | F11: =_xlfn.XLOOKUP(B11,purchase_orders!C:C,purchase_orders!G:G) -> 46050 | G11: =TODAY()-F11 -> 114 | H11: =IF(G11<=30,"0-30",IF(G11<=60,"31-60",IF(G11<=90,"61-90","90+"))) -> 90+ | I11: =SUMIFS(order_items!D:D,order_items!C:C,inventory!B11) -> 51 | J11: =IF(D11>I11*3,"Overstock","OK") -> Overstock | K11: =IFERROR(_xlfn.XLOOKUP(B11,purchase_orders!C:C,purchase_orders!I:I),0) -> 392 | L11: =(D11+K11)/2 -> 356 | M11: =IFERROR(ROUND(I11/L11,2),0) -> 0.14 | N11: =IFERROR(_xlfn.XLOOKUP(B11,products!A:A,products!E:E),0) -> 21.93 | O11: =IF(N11="NULL",0,N11*D11) -> 7017.6 | P11: =IF(I11<10,"Slow Moving","Normal") -> Normal | Q11: =IFERROR(_xlfn.XLOOKUP(B11,reorder_point!B:B,reorder_point!I:I),"") -> OK | R11: =_xlfn.XLOOKUP(B11,products!A:A,products!B:B) -> SKU-0006
